<?xml version="1.0"?>
<robot xmlns:xacro="http://www.ros.org/wiki/xacro" name="robot">
  <link name="base">
    <visual>
      <geometry>
        <box size="0.94 0.78 1.98"/>
      </geometry>
	<origin xyz="0 0 0.99"/>
    </visual>
    <collision>
      <geometry>
        <box size="0.94 0.78 1.98"/>
      </geometry>
    </collision>
  </link>
	<!-- Include the XACRO file that defines a Hokuyo LIDAR. -->
	<xacro:include filename="$(find gazebo_plugins)/test/multi_robot_scenario/xacro/laser/hokuyo.xacro" />
	<xacro:laser name="laser_vert_bottom" parent="base" xyz="0.3157894464801903 -0.002068548615034871 0.5099999434059285" rpy="3.1354753 -1.3045001 0.0024658" meshes="package://gazebo_plugins/test/multi_robot_scenario/meshes/laser" />
	<xacro:laser name="laser_vert_top_left" parent="base" xyz="0.2997 0.1531 1.8443" rpy="1.1780 0.6198 0.087" meshes="package://gazebo_plugins/test/multi_robot_scenario/meshes/laser" />
	<xacro:laser name="laser_vert_top_right" parent="base" xyz="0.2978 -0.1450 1.8451" rpy="-1.1760 0.6313 -1.9377" meshes="package://gazebo_plugins/test/multi_robot_scenario/meshes/laser" />
	<!-- Include the XACRO file that defines a Hokuyo LIDAR. -->
	<xacro:include filename="$(find velodyne_description)/urdf/VLP-16.urdf.xacro"/>
	<!-- Invoke the macro to define the Hokuyo LIDAR. -->
	<VLP-16 parent="base" name="laser_horiz" topic="laser_horiz/packets" hz="10"
	samples="440" gpu="false">
	<origin xyz="0.2325416305773505 -0.0001380069427607134 1.920122926231907"
	rpy="-0.0012068 0.114646 -0.0015308" />
	</VLP-16>
  <xacro:macro name="xacro_name" params="suffix reflect center">
  <link name="wheel_${suffix}">
    <visual>
      <geometry>
        <cylinder radius="${0.2 - center * 0.05}" length="0.05" />
      </geometry>
	<origin rpy="-1.57079 0 0" xyz="${-0.1 +  0.2 * center} ${reflect * 0.2} ${-0.025 * center}"/>
    </visual>
    <collision>
      <geometry>
      	<cylinder radius="${0.2 - center * 0.05}" length="0.05" />
      </geometry>
			<origin rpy="-1.57079 0 0" xyz="${-0.1 +  0.2 * center} ${reflect * 0.2} ${-0.025 * center}"/>
    </collision>
  </link>
  <joint name="base_wheel_${suffix}_joint" type="continuous">
	<parent link="base"/>
	<child link="wheel_${suffix}"/>
	<origin xyz="${-0.1 +  0.2 * center} ${reflect * 0.4} ${-0.025 * center}" rpy="0 -1.57079 0"/>
	<limit velocity = "1" effort = "1"/>
  </joint>
  </xacro:macro>
  <xacro:xacro_name suffix="left" reflect="1" center="0"/>
	<xacro:xacro_name suffix="right" reflect="-1" center="0"/>
	<xacro:xacro_name suffix="center" reflect="0" center="1"/>
</robot>
